package com.jtrent238.foodmod;
import cpw.mods.fml.client.*;
import cpw.mods.fml.client.registry.*;
import cpw.mods.fml.common.*;
import cpw.mods.fml.common.asm.*;
import cpw.mods.fml.common.asm.transformers.*;
import cpw.mods.fml.common.discovery.*;
import cpw.mods.fml.common.discovery.asm.*;
import cpw.mods.fml.common.event.*;
import cpw.mods.fml.common.functions.*;
import cpw.mods.fml.common.network.*;
import cpw.mods.fml.common.registry.*;
import cpw.mods.fml.common.toposort.*;
import cpw.mods.fml.common.versioning.*;
import cpw.mods.fml.relauncher.*;
import cpw.mods.fml.server.*;
import net.minecraft.block.*;
import net.minecraft.block.material.*;
import net.minecraft.client.*;
import net.minecraft.client.audio.*;
import net.minecraft.client.entity.*;
import net.minecraft.client.gui.*;
import net.minecraft.client.gui.achievement.*;
import net.minecraft.client.gui.inventory.*;
import net.minecraft.client.model.*;
import net.minecraft.client.multiplayer.*;
import net.minecraft.client.particle.*;
import net.minecraft.client.renderer.*;
import net.minecraft.client.renderer.culling.*;
import net.minecraft.client.renderer.entity.*;
import net.minecraft.client.renderer.tileentity.*;
import net.minecraft.client.settings.*;
import net.minecraft.command.*;
import net.minecraft.crash.*;
import net.minecraft.creativetab.*;
import net.minecraft.dispenser.*;
import net.minecraft.enchantment.*;
import net.minecraft.entity.*;
import net.minecraft.entity.ai.*;
import net.minecraft.entity.boss.*;
import net.minecraft.entity.effect.*;
import net.minecraft.entity.item.*;
import net.minecraft.entity.monster.*;
import net.minecraft.entity.passive.*;
import net.minecraft.entity.player.*;
import net.minecraft.entity.projectile.*;
import net.minecraft.inventory.*;
import net.minecraft.item.*;
import net.minecraft.item.crafting.*;
import net.minecraft.nbt.*;
import net.minecraft.network.*;
import net.minecraft.network.rcon.*;
import net.minecraft.pathfinding.*;
import net.minecraft.potion.*;
import net.minecraft.profiler.*;
import net.minecraft.server.*;
import net.minecraft.server.dedicated.*;
import net.minecraft.server.gui.*;
import net.minecraft.server.integrated.*;
import net.minecraft.server.management.*;
import net.minecraft.src.*;
import net.minecraft.stats.*;
import net.minecraft.tileentity.*;
import net.minecraft.util.*;
import net.minecraft.village.*;
import net.minecraft.world.*;
import net.minecraft.world.biome.*;
import net.minecraft.world.chunk.*;
import net.minecraft.world.chunk.storage.*;
import net.minecraft.world.demo.*;
import net.minecraft.world.gen.*;
import net.minecraft.world.gen.feature.*;
import net.minecraft.world.gen.layer.*;
import net.minecraft.world.gen.structure.*;
import net.minecraft.world.storage.*;
import net.minecraftforge.classloading.*;
import net.minecraftforge.client.*;
import net.minecraftforge.client.event.*;
import net.minecraftforge.client.event.sound.*;
import net.minecraftforge.common.*;
import net.minecraftforge.event.*;
import net.minecraftforge.event.entity.*;
import net.minecraftforge.event.entity.item.*;
import net.minecraftforge.event.entity.living.*;
import net.minecraftforge.event.entity.minecart.*;
import net.minecraftforge.event.entity.player.*;
import net.minecraftforge.event.terraingen.*;
import net.minecraftforge.event.world.*;
import net.minecraftforge.oredict.*;
import net.minecraftforge.transformers.*;
import net.minecraft.init.*;
import java.util.*;
import net.minecraftforge.common.util.*;

import org.lwjgl.opengl.GL11;



@SuppressWarnings("unchecked")
public class Itemcandycanestructure extends Item{

public Itemcandycanestructure(){}

public static Item block;public static Object instance;public void load(){
}
public void generateNether(World world, Random random, int chunkX, int chunkZ){}
public void generateSurface(World world, Random random, int chunkX, int chunkZ){}
public int addFuel(ItemStack fuel){return 0;}
public void serverLoad(FMLServerStartingEvent event){}
public void preInit(FMLPreInitializationEvent event){}
public void registerRenderers(){
}




static class ItemtestItem extends Item{

public ItemtestItem(int par1){
setMaxDamage(0);
maxStackSize = 64;
setUnlocalizedName("Itemcandycanestructurespawner");
setTextureName("foodmod:itemcandycanestructure");
setCreativeTab(FoodMod.TestStuff);
}
public int getItemEnchantability()
{
    return 0;
}
public int getMaxItemUseDuration(ItemStack par1ItemStack)
{
    return 0;
}
public float getStrVsBlock(ItemStack par1ItemStack, Block par2Block)
{
    return 1.0F;
}
public boolean onItemUse(ItemStack itemStack, EntityPlayer entity, World world, int i, int j, int k, int l, float a, float b, float c){
float var4 = 1.0F;

if(true){
boolean place = true;

if(place){
world.setBlock(i+0, j+0, k+0, Block.getBlockById(80), 0, 2);
world.setBlock(i+1, j+0, k+0, Block.getBlockById(80), 0, 2);
world.setBlock(i+2, j+0, k+0, Block.getBlockById(80), 0, 2);
world.setBlock(i+3, j+0, k+0, Block.getBlockById(80), 0, 2);
world.setBlock(i+4, j+0, k+0, Block.getBlockById(2), 0, 2);
world.setBlock(i+0, j+0, k+1, Block.getBlockById(2), 0, 2);
world.setBlock(i+1, j+0, k+1, Block.getBlockById(80), 0, 2);
world.setBlock(i+2, j+0, k+1, Block.getBlockById(80), 0, 2);
world.setBlock(i+3, j+0, k+1, Block.getBlockById(80), 0, 2);
world.setBlock(i+4, j+0, k+1, Block.getBlockById(2), 0, 2);
world.setBlock(i+0, j+0, k+2, Block.getBlockById(2), 0, 2);
world.setBlock(i+1, j+0, k+2, Block.getBlockById(80), 0, 2);
world.setBlock(i+2, j+0, k+2, Block.getBlockById(80), 0, 2);
world.setBlock(i+3, j+0, k+2, Block.getBlockById(80), 0, 2);
world.setBlock(i+4, j+0, k+2, Block.getBlockById(2), 0, 2);
world.setBlock(i+0, j+0, k+3, Block.getBlockById(2), 0, 2);
world.setBlock(i+1, j+0, k+3, Block.getBlockById(80), 0, 2);
world.setBlock(i+2, j+0, k+3, Block.getBlockById(80), 0, 2);
world.setBlock(i+3, j+0, k+3, Block.getBlockById(80), 0, 2);
world.setBlock(i+4, j+0, k+3, Block.getBlockById(2), 0, 2);
world.setBlock(i+0, j+0, k+4, Block.getBlockById(2), 0, 2);
world.setBlock(i+1, j+0, k+4, Block.getBlockById(80), 0, 2);
world.setBlock(i+2, j+0, k+4, Block.getBlockById(80), 0, 2);
world.setBlock(i+3, j+0, k+4, Block.getBlockById(80), 0, 2);
world.setBlock(i+4, j+0, k+4, Block.getBlockById(2), 0, 2);
world.setBlock(i+0, j+0, k+5, Block.getBlockById(2), 0, 2);
world.setBlock(i+1, j+0, k+5, Block.getBlockById(80), 0, 2);
world.setBlock(i+2, j+0, k+5, Block.getBlockById(80), 0, 2);
world.setBlock(i+3, j+0, k+5, Block.getBlockById(80), 0, 2);
world.setBlock(i+4, j+0, k+5, Block.getBlockById(2), 0, 2);
world.setBlock(i+0, j+0, k+6, Block.getBlockById(2), 0, 2);
world.setBlock(i+1, j+0, k+6, Block.getBlockById(80), 0, 2);
world.setBlock(i+2, j+0, k+6, Block.getBlockById(80), 0, 2);
world.setBlock(i+3, j+0, k+6, Block.getBlockById(80), 0, 2);
world.setBlock(i+4, j+0, k+6, Block.getBlockById(2), 0, 2);
world.setBlock(i+0, j+0, k+7, Block.getBlockById(2), 0, 2);
world.setBlock(i+1, j+0, k+7, Block.getBlockById(80), 0, 2);
world.setBlock(i+2, j+0, k+7, Block.getBlockById(80), 0, 2);
world.setBlock(i+3, j+0, k+7, Block.getBlockById(80), 0, 2);
world.setBlock(i+4, j+0, k+7, Block.getBlockById(2), 0, 2);
world.setBlock(i+0, j+0, k+8, Block.getBlockById(2), 0, 2);
world.setBlock(i+1, j+0, k+8, Block.getBlockById(80), 0, 2);
world.setBlock(i+2, j+0, k+8, Block.getBlockById(80), 0, 2);
world.setBlock(i+3, j+0, k+8, Block.getBlockById(80), 0, 2);
world.setBlock(i+4, j+0, k+8, Block.getBlockById(2), 0, 2);
world.setBlock(i+0, j+0, k+9, Block.getBlockById(2), 0, 2);
world.setBlock(i+1, j+0, k+9, Block.getBlockById(3), 0, 2);
world.setBlock(i+2, j+0, k+9, Block.getBlockById(80), 0, 2);
world.setBlock(i+3, j+0, k+9, Block.getBlockById(3), 0, 2);
world.setBlock(i+4, j+0, k+9, Block.getBlockById(2), 0, 2);
world.setBlock(i+0, j+0, k+10, Block.getBlockById(3), 0, 2);
world.setBlock(i+1, j+0, k+10, Block.getBlockById(3), 0, 2);
world.setBlock(i+2, j+0, k+10, Block.getBlockById(3), 0, 2);
world.setBlock(i+3, j+0, k+10, Block.getBlockById(3), 0, 2);
world.setBlock(i+4, j+0, k+10, Block.getBlockById(3), 0, 2);
world.setBlock(i+0, j+0, k+11, Block.getBlockById(3), 0, 2);
world.setBlock(i+1, j+0, k+11, Block.getBlockById(3), 0, 2);
world.setBlock(i+2, j+0, k+11, Block.getBlockById(3), 0, 2);
world.setBlock(i+3, j+0, k+11, Block.getBlockById(3), 0, 2);
world.setBlock(i+4, j+0, k+11, Block.getBlockById(3), 0, 2);
world.setBlock(i+0, j+0, k+12, Block.getBlockById(3), 0, 2);
world.setBlock(i+1, j+0, k+12, Block.getBlockById(3), 0, 2);
world.setBlock(i+2, j+0, k+12, Block.getBlockById(3), 0, 2);
world.setBlock(i+3, j+0, k+12, Block.getBlockById(3), 0, 2);
world.setBlock(i+4, j+0, k+12, Block.getBlockById(3), 0, 2);
world.setBlock(i+0, j+0, k+13, Block.getBlockById(2), 0, 2);
world.setBlock(i+1, j+0, k+13, Block.getBlockById(3), 0, 2);
world.setBlock(i+2, j+0, k+13, Block.getBlockById(3), 0, 2);
world.setBlock(i+3, j+0, k+13, Block.getBlockById(3), 0, 2);
world.setBlock(i+4, j+0, k+13, Block.getBlockById(2), 0, 2);
world.setBlock(i+0, j+0, k+14, Block.getBlockById(80), 0, 2);
world.setBlock(i+1, j+0, k+14, Block.getBlockById(80), 0, 2);
world.setBlock(i+2, j+0, k+14, Block.getBlockById(80), 0, 2);
world.setBlock(i+3, j+0, k+14, Block.getBlockById(80), 0, 2);
world.setBlock(i+4, j+0, k+14, Block.getBlockById(80), 0, 2);
world.setBlock(i+4, j+1, k+0, Block.getBlockById(78), 0, 2);
world.setBlock(i+0, j+1, k+1, Block.getBlockById(78), 0, 2);
world.setBlock(i+1, j+1, k+1, Block.getBlockById(78), 0, 2);
world.setBlock(i+3, j+1, k+1, Block.getBlockById(78), 0, 2);
world.setBlock(i+4, j+1, k+1, Block.getBlockById(78), 0, 2);
world.setBlock(i+0, j+1, k+2, Block.getBlockById(78), 0, 2);
world.setBlock(i+1, j+1, k+2, Block.getBlockById(78), 0, 2);
world.setBlock(i+3, j+1, k+2, Block.getBlockById(78), 0, 2);
world.setBlock(i+4, j+1, k+2, Block.getBlockById(78), 0, 2);
world.setBlock(i+0, j+1, k+3, Block.getBlockById(78), 0, 2);
world.setBlock(i+1, j+1, k+3, Block.getBlockById(78), 0, 2);
world.setBlock(i+3, j+1, k+3, Block.getBlockById(78), 0, 2);
world.setBlock(i+4, j+1, k+3, Block.getBlockById(78), 0, 2);
world.setBlock(i+0, j+1, k+4, Block.getBlockById(78), 0, 2);
world.setBlock(i+1, j+1, k+4, Block.getBlockById(78), 0, 2);
world.setBlock(i+3, j+1, k+4, Block.getBlockById(78), 0, 2);
world.setBlock(i+4, j+1, k+4, Block.getBlockById(78), 0, 2);
world.setBlock(i+0, j+1, k+5, Block.getBlockById(78), 0, 2);
world.setBlock(i+1, j+1, k+5, Block.getBlockById(78), 0, 2);
world.setBlock(i+3, j+1, k+5, Block.getBlockById(78), 0, 2);
world.setBlock(i+4, j+1, k+5, Block.getBlockById(78), 0, 2);
world.setBlock(i+0, j+1, k+6, Block.getBlockById(78), 0, 2);
world.setBlock(i+1, j+1, k+6, Block.getBlockById(78), 0, 2);
world.setBlock(i+3, j+1, k+6, Block.getBlockById(78), 0, 2);
world.setBlock(i+4, j+1, k+6, Block.getBlockById(78), 0, 2);
world.setBlock(i+0, j+1, k+7, Block.getBlockById(78), 0, 2);
world.setBlock(i+1, j+1, k+7, Block.getBlockById(78), 0, 2);
world.setBlock(i+3, j+1, k+7, Block.getBlockById(78), 0, 2);
world.setBlock(i+4, j+1, k+7, Block.getBlockById(78), 0, 2);
world.setBlock(i+0, j+1, k+8, Block.getBlockById(78), 0, 2);
world.setBlock(i+1, j+1, k+8, Block.getBlockById(78), 0, 2);
world.setBlock(i+3, j+1, k+8, Block.getBlockById(78), 0, 2);
world.setBlock(i+4, j+1, k+8, Block.getBlockById(78), 0, 2);
world.setBlock(i+0, j+1, k+9, Block.getBlockById(78), 0, 2);
world.setBlock(i+1, j+1, k+9, Block.getBlockById(35), 0, 2);
world.setBlock(i+2, j+1, k+9, Block.getBlockById(35), 0, 2);
world.setBlock(i+3, j+1, k+9, Block.getBlockById(35), 0, 2);
world.setBlock(i+4, j+1, k+9, Block.getBlockById(78), 0, 2);
world.setBlock(i+0, j+1, k+10, Block.getBlockById(35), 0, 2);
world.setBlock(i+1, j+1, k+10, Block.getBlockById(35), 0, 2);
world.setBlock(i+2, j+1, k+10, Block.getBlockById(35), 0, 2);
world.setBlock(i+3, j+1, k+10, Block.getBlockById(35), 0, 2);
world.setBlock(i+4, j+1, k+10, Block.getBlockById(35), 0, 2);
world.setBlock(i+0, j+1, k+11, Block.getBlockById(35), 0, 2);
world.setBlock(i+1, j+1, k+11, Block.getBlockById(35), 0, 2);
world.setBlock(i+2, j+1, k+11, Block.getBlockById(35), 0, 2);
world.setBlock(i+3, j+1, k+11, Block.getBlockById(35), 0, 2);
world.setBlock(i+4, j+1, k+11, Block.getBlockById(35), 0, 2);
world.setBlock(i+0, j+1, k+12, Block.getBlockById(35), 0, 2);
world.setBlock(i+1, j+1, k+12, Block.getBlockById(35), 0, 2);
world.setBlock(i+2, j+1, k+12, Block.getBlockById(35), 0, 2);
world.setBlock(i+3, j+1, k+12, Block.getBlockById(35), 0, 2);
world.setBlock(i+4, j+1, k+12, Block.getBlockById(35), 0, 2);
world.setBlock(i+1, j+1, k+13, Block.getBlockById(35), 0, 2);
world.setBlock(i+2, j+1, k+13, Block.getBlockById(35), 0, 2);
world.setBlock(i+3, j+1, k+13, Block.getBlockById(35), 0, 2);
world.setBlock(i+4, j+1, k+13, Block.getBlockById(78), 0, 2);
world.setBlock(i+0, j+1, k+14, Block.getBlockById(78), 0, 2);
world.setBlock(i+1, j+1, k+14, Block.getBlockById(78), 0, 2);
world.setBlock(i+2, j+1, k+14, Block.getBlockById(78), 0, 2);
world.setBlock(i+3, j+1, k+14, Block.getBlockById(78), 0, 2);
world.setBlock(i+4, j+1, k+14, Block.getBlockById(78), 0, 2);
world.setBlock(i+1, j+2, k+9, Block.getBlockById(35), 14, 2);
world.setBlock(i+2, j+2, k+9, Block.getBlockById(35), 14, 2);
world.setBlock(i+3, j+2, k+9, Block.getBlockById(35), 14, 2);
world.setBlock(i+0, j+2, k+10, Block.getBlockById(35), 14, 2);
world.setBlock(i+1, j+2, k+10, Block.getBlockById(35), 0, 2);
world.setBlock(i+2, j+2, k+10, Block.getBlockById(35), 0, 2);
world.setBlock(i+3, j+2, k+10, Block.getBlockById(35), 0, 2);
world.setBlock(i+4, j+2, k+10, Block.getBlockById(35), 14, 2);
world.setBlock(i+0, j+2, k+11, Block.getBlockById(35), 14, 2);
world.setBlock(i+1, j+2, k+11, Block.getBlockById(35), 0, 2);
world.setBlock(i+2, j+2, k+11, Block.getBlockById(35), 0, 2);
world.setBlock(i+3, j+2, k+11, Block.getBlockById(35), 0, 2);
world.setBlock(i+4, j+2, k+11, Block.getBlockById(35), 14, 2);
world.setBlock(i+0, j+2, k+12, Block.getBlockById(35), 14, 2);
world.setBlock(i+1, j+2, k+12, Block.getBlockById(35), 0, 2);
world.setBlock(i+2, j+2, k+12, Block.getBlockById(35), 0, 2);
world.setBlock(i+3, j+2, k+12, Block.getBlockById(35), 0, 2);
world.setBlock(i+4, j+2, k+12, Block.getBlockById(35), 14, 2);
world.setBlock(i+1, j+2, k+13, Block.getBlockById(35), 14, 2);
world.setBlock(i+2, j+2, k+13, Block.getBlockById(35), 14, 2);
world.setBlock(i+3, j+2, k+13, Block.getBlockById(35), 14, 2);
world.setBlock(i+1, j+3, k+9, Block.getBlockById(35), 0, 2);
world.setBlock(i+2, j+3, k+9, Block.getBlockById(35), 0, 2);
world.setBlock(i+3, j+3, k+9, Block.getBlockById(35), 0, 2);
world.setBlock(i+0, j+3, k+10, Block.getBlockById(35), 0, 2);
world.setBlock(i+1, j+3, k+10, Block.getBlockById(35), 0, 2);
world.setBlock(i+2, j+3, k+10, Block.getBlockById(35), 0, 2);
world.setBlock(i+3, j+3, k+10, Block.getBlockById(35), 0, 2);
world.setBlock(i+4, j+3, k+10, Block.getBlockById(35), 0, 2);
world.setBlock(i+0, j+3, k+11, Block.getBlockById(35), 0, 2);
world.setBlock(i+1, j+3, k+11, Block.getBlockById(35), 0, 2);
world.setBlock(i+2, j+3, k+11, Block.getBlockById(35), 0, 2);
world.setBlock(i+3, j+3, k+11, Block.getBlockById(35), 0, 2);
world.setBlock(i+4, j+3, k+11, Block.getBlockById(35), 0, 2);
world.setBlock(i+0, j+3, k+12, Block.getBlockById(35), 0, 2);
world.setBlock(i+1, j+3, k+12, Block.getBlockById(35), 0, 2);
world.setBlock(i+2, j+3, k+12, Block.getBlockById(35), 0, 2);
world.setBlock(i+3, j+3, k+12, Block.getBlockById(35), 0, 2);
world.setBlock(i+4, j+3, k+12, Block.getBlockById(35), 0, 2);
world.setBlock(i+1, j+3, k+13, Block.getBlockById(35), 0, 2);
world.setBlock(i+2, j+3, k+13, Block.getBlockById(35), 0, 2);
world.setBlock(i+3, j+3, k+13, Block.getBlockById(35), 0, 2);
world.setBlock(i+1, j+4, k+9, Block.getBlockById(35), 14, 2);
world.setBlock(i+2, j+4, k+9, Block.getBlockById(35), 14, 2);
world.setBlock(i+3, j+4, k+9, Block.getBlockById(35), 14, 2);
world.setBlock(i+0, j+4, k+10, Block.getBlockById(35), 14, 2);
world.setBlock(i+1, j+4, k+10, Block.getBlockById(35), 0, 2);
world.setBlock(i+2, j+4, k+10, Block.getBlockById(35), 0, 2);
world.setBlock(i+3, j+4, k+10, Block.getBlockById(35), 0, 2);
world.setBlock(i+4, j+4, k+10, Block.getBlockById(35), 14, 2);
world.setBlock(i+0, j+4, k+11, Block.getBlockById(35), 14, 2);
world.setBlock(i+1, j+4, k+11, Block.getBlockById(35), 0, 2);
world.setBlock(i+2, j+4, k+11, Block.getBlockById(35), 0, 2);
world.setBlock(i+3, j+4, k+11, Block.getBlockById(35), 0, 2);
world.setBlock(i+4, j+4, k+11, Block.getBlockById(35), 14, 2);
world.setBlock(i+0, j+4, k+12, Block.getBlockById(35), 14, 2);
world.setBlock(i+1, j+4, k+12, Block.getBlockById(35), 0, 2);
world.setBlock(i+2, j+4, k+12, Block.getBlockById(35), 0, 2);
world.setBlock(i+3, j+4, k+12, Block.getBlockById(35), 0, 2);
world.setBlock(i+4, j+4, k+12, Block.getBlockById(35), 14, 2);
world.setBlock(i+1, j+4, k+13, Block.getBlockById(35), 14, 2);
world.setBlock(i+2, j+4, k+13, Block.getBlockById(35), 14, 2);
world.setBlock(i+3, j+4, k+13, Block.getBlockById(35), 14, 2);
world.setBlock(i+1, j+5, k+9, Block.getBlockById(35), 0, 2);
world.setBlock(i+2, j+5, k+9, Block.getBlockById(35), 0, 2);
world.setBlock(i+3, j+5, k+9, Block.getBlockById(35), 0, 2);
world.setBlock(i+0, j+5, k+10, Block.getBlockById(35), 0, 2);
world.setBlock(i+1, j+5, k+10, Block.getBlockById(35), 0, 2);
world.setBlock(i+2, j+5, k+10, Block.getBlockById(35), 0, 2);
world.setBlock(i+3, j+5, k+10, Block.getBlockById(35), 0, 2);
world.setBlock(i+4, j+5, k+10, Block.getBlockById(35), 0, 2);
world.setBlock(i+0, j+5, k+11, Block.getBlockById(35), 0, 2);
world.setBlock(i+1, j+5, k+11, Block.getBlockById(35), 0, 2);
world.setBlock(i+2, j+5, k+11, Block.getBlockById(35), 0, 2);
world.setBlock(i+3, j+5, k+11, Block.getBlockById(35), 0, 2);
world.setBlock(i+4, j+5, k+11, Block.getBlockById(35), 0, 2);
world.setBlock(i+0, j+5, k+12, Block.getBlockById(35), 0, 2);
world.setBlock(i+1, j+5, k+12, Block.getBlockById(35), 0, 2);
world.setBlock(i+2, j+5, k+12, Block.getBlockById(35), 0, 2);
world.setBlock(i+3, j+5, k+12, Block.getBlockById(35), 0, 2);
world.setBlock(i+4, j+5, k+12, Block.getBlockById(35), 0, 2);
world.setBlock(i+1, j+5, k+13, Block.getBlockById(35), 0, 2);
world.setBlock(i+2, j+5, k+13, Block.getBlockById(35), 0, 2);
world.setBlock(i+3, j+5, k+13, Block.getBlockById(35), 0, 2);
world.setBlock(i+1, j+6, k+9, Block.getBlockById(35), 14, 2);
world.setBlock(i+2, j+6, k+9, Block.getBlockById(35), 14, 2);
world.setBlock(i+3, j+6, k+9, Block.getBlockById(35), 14, 2);
world.setBlock(i+0, j+6, k+10, Block.getBlockById(35), 14, 2);
world.setBlock(i+1, j+6, k+10, Block.getBlockById(35), 0, 2);
world.setBlock(i+2, j+6, k+10, Block.getBlockById(35), 0, 2);
world.setBlock(i+3, j+6, k+10, Block.getBlockById(35), 0, 2);
world.setBlock(i+4, j+6, k+10, Block.getBlockById(35), 14, 2);
world.setBlock(i+0, j+6, k+11, Block.getBlockById(35), 14, 2);
world.setBlock(i+1, j+6, k+11, Block.getBlockById(35), 0, 2);
world.setBlock(i+2, j+6, k+11, Block.getBlockById(35), 0, 2);
world.setBlock(i+3, j+6, k+11, Block.getBlockById(35), 0, 2);
world.setBlock(i+4, j+6, k+11, Block.getBlockById(35), 14, 2);
world.setBlock(i+0, j+6, k+12, Block.getBlockById(35), 14, 2);
world.setBlock(i+1, j+6, k+12, Block.getBlockById(35), 0, 2);
world.setBlock(i+2, j+6, k+12, Block.getBlockById(35), 0, 2);
world.setBlock(i+3, j+6, k+12, Block.getBlockById(35), 0, 2);
world.setBlock(i+4, j+6, k+12, Block.getBlockById(35), 14, 2);
world.setBlock(i+1, j+6, k+13, Block.getBlockById(35), 14, 2);
world.setBlock(i+2, j+6, k+13, Block.getBlockById(35), 14, 2);
world.setBlock(i+3, j+6, k+13, Block.getBlockById(35), 14, 2);
world.setBlock(i+1, j+7, k+9, Block.getBlockById(35), 0, 2);
world.setBlock(i+2, j+7, k+9, Block.getBlockById(35), 0, 2);
world.setBlock(i+3, j+7, k+9, Block.getBlockById(35), 0, 2);
world.setBlock(i+0, j+7, k+10, Block.getBlockById(35), 0, 2);
world.setBlock(i+1, j+7, k+10, Block.getBlockById(35), 0, 2);
world.setBlock(i+2, j+7, k+10, Block.getBlockById(35), 0, 2);
world.setBlock(i+3, j+7, k+10, Block.getBlockById(35), 0, 2);
world.setBlock(i+4, j+7, k+10, Block.getBlockById(35), 0, 2);
world.setBlock(i+0, j+7, k+11, Block.getBlockById(35), 0, 2);
world.setBlock(i+1, j+7, k+11, Block.getBlockById(35), 0, 2);
world.setBlock(i+2, j+7, k+11, Block.getBlockById(35), 0, 2);
world.setBlock(i+3, j+7, k+11, Block.getBlockById(35), 0, 2);
world.setBlock(i+4, j+7, k+11, Block.getBlockById(35), 0, 2);
world.setBlock(i+0, j+7, k+12, Block.getBlockById(35), 0, 2);
world.setBlock(i+1, j+7, k+12, Block.getBlockById(35), 0, 2);
world.setBlock(i+2, j+7, k+12, Block.getBlockById(35), 0, 2);
world.setBlock(i+3, j+7, k+12, Block.getBlockById(35), 0, 2);
world.setBlock(i+4, j+7, k+12, Block.getBlockById(35), 0, 2);
world.setBlock(i+1, j+7, k+13, Block.getBlockById(35), 0, 2);
world.setBlock(i+2, j+7, k+13, Block.getBlockById(35), 0, 2);
world.setBlock(i+3, j+7, k+13, Block.getBlockById(35), 0, 2);
world.setBlock(i+1, j+8, k+9, Block.getBlockById(35), 14, 2);
world.setBlock(i+2, j+8, k+9, Block.getBlockById(35), 14, 2);
world.setBlock(i+3, j+8, k+9, Block.getBlockById(35), 14, 2);
world.setBlock(i+0, j+8, k+10, Block.getBlockById(35), 14, 2);
world.setBlock(i+1, j+8, k+10, Block.getBlockById(35), 0, 2);
world.setBlock(i+2, j+8, k+10, Block.getBlockById(35), 0, 2);
world.setBlock(i+3, j+8, k+10, Block.getBlockById(35), 0, 2);
world.setBlock(i+4, j+8, k+10, Block.getBlockById(35), 14, 2);
world.setBlock(i+0, j+8, k+11, Block.getBlockById(35), 14, 2);
world.setBlock(i+1, j+8, k+11, Block.getBlockById(35), 0, 2);
world.setBlock(i+2, j+8, k+11, Block.getBlockById(35), 0, 2);
world.setBlock(i+3, j+8, k+11, Block.getBlockById(35), 0, 2);
world.setBlock(i+4, j+8, k+11, Block.getBlockById(35), 14, 2);
world.setBlock(i+0, j+8, k+12, Block.getBlockById(35), 14, 2);
world.setBlock(i+1, j+8, k+12, Block.getBlockById(35), 0, 2);
world.setBlock(i+2, j+8, k+12, Block.getBlockById(35), 0, 2);
world.setBlock(i+3, j+8, k+12, Block.getBlockById(35), 0, 2);
world.setBlock(i+4, j+8, k+12, Block.getBlockById(35), 14, 2);
world.setBlock(i+1, j+8, k+13, Block.getBlockById(35), 14, 2);
world.setBlock(i+2, j+8, k+13, Block.getBlockById(35), 14, 2);
world.setBlock(i+3, j+8, k+13, Block.getBlockById(35), 14, 2);
world.setBlock(i+1, j+9, k+9, Block.getBlockById(35), 0, 2);
world.setBlock(i+2, j+9, k+9, Block.getBlockById(35), 0, 2);
world.setBlock(i+3, j+9, k+9, Block.getBlockById(35), 0, 2);
world.setBlock(i+0, j+9, k+10, Block.getBlockById(35), 0, 2);
world.setBlock(i+1, j+9, k+10, Block.getBlockById(35), 0, 2);
world.setBlock(i+2, j+9, k+10, Block.getBlockById(35), 0, 2);
world.setBlock(i+3, j+9, k+10, Block.getBlockById(35), 0, 2);
world.setBlock(i+4, j+9, k+10, Block.getBlockById(35), 0, 2);
world.setBlock(i+0, j+9, k+11, Block.getBlockById(35), 0, 2);
world.setBlock(i+1, j+9, k+11, Block.getBlockById(35), 0, 2);
world.setBlock(i+2, j+9, k+11, Block.getBlockById(35), 0, 2);
world.setBlock(i+3, j+9, k+11, Block.getBlockById(35), 0, 2);
world.setBlock(i+4, j+9, k+11, Block.getBlockById(35), 0, 2);
world.setBlock(i+0, j+9, k+12, Block.getBlockById(35), 0, 2);
world.setBlock(i+1, j+9, k+12, Block.getBlockById(35), 0, 2);
world.setBlock(i+2, j+9, k+12, Block.getBlockById(35), 0, 2);
world.setBlock(i+3, j+9, k+12, Block.getBlockById(35), 0, 2);
world.setBlock(i+4, j+9, k+12, Block.getBlockById(35), 0, 2);
world.setBlock(i+1, j+9, k+13, Block.getBlockById(35), 0, 2);
world.setBlock(i+2, j+9, k+13, Block.getBlockById(35), 0, 2);
world.setBlock(i+3, j+9, k+13, Block.getBlockById(35), 0, 2);
world.setBlock(i+1, j+10, k+9, Block.getBlockById(35), 14, 2);
world.setBlock(i+2, j+10, k+9, Block.getBlockById(35), 14, 2);
world.setBlock(i+3, j+10, k+9, Block.getBlockById(35), 14, 2);
world.setBlock(i+0, j+10, k+10, Block.getBlockById(35), 14, 2);
world.setBlock(i+1, j+10, k+10, Block.getBlockById(35), 0, 2);
world.setBlock(i+2, j+10, k+10, Block.getBlockById(35), 0, 2);
world.setBlock(i+3, j+10, k+10, Block.getBlockById(35), 0, 2);
world.setBlock(i+4, j+10, k+10, Block.getBlockById(35), 14, 2);
world.setBlock(i+0, j+10, k+11, Block.getBlockById(35), 14, 2);
world.setBlock(i+1, j+10, k+11, Block.getBlockById(35), 0, 2);
world.setBlock(i+2, j+10, k+11, Block.getBlockById(35), 0, 2);
world.setBlock(i+3, j+10, k+11, Block.getBlockById(35), 0, 2);
world.setBlock(i+4, j+10, k+11, Block.getBlockById(35), 14, 2);
world.setBlock(i+0, j+10, k+12, Block.getBlockById(35), 14, 2);
world.setBlock(i+1, j+10, k+12, Block.getBlockById(35), 0, 2);
world.setBlock(i+2, j+10, k+12, Block.getBlockById(35), 0, 2);
world.setBlock(i+3, j+10, k+12, Block.getBlockById(35), 0, 2);
world.setBlock(i+4, j+10, k+12, Block.getBlockById(35), 14, 2);
world.setBlock(i+1, j+10, k+13, Block.getBlockById(35), 14, 2);
world.setBlock(i+2, j+10, k+13, Block.getBlockById(35), 14, 2);
world.setBlock(i+3, j+10, k+13, Block.getBlockById(35), 14, 2);
world.setBlock(i+1, j+11, k+9, Block.getBlockById(35), 0, 2);
world.setBlock(i+2, j+11, k+9, Block.getBlockById(35), 0, 2);
world.setBlock(i+3, j+11, k+9, Block.getBlockById(35), 0, 2);
world.setBlock(i+0, j+11, k+10, Block.getBlockById(35), 0, 2);
world.setBlock(i+1, j+11, k+10, Block.getBlockById(35), 0, 2);
world.setBlock(i+2, j+11, k+10, Block.getBlockById(35), 0, 2);
world.setBlock(i+3, j+11, k+10, Block.getBlockById(35), 0, 2);
world.setBlock(i+4, j+11, k+10, Block.getBlockById(35), 0, 2);
world.setBlock(i+0, j+11, k+11, Block.getBlockById(35), 0, 2);
world.setBlock(i+1, j+11, k+11, Block.getBlockById(35), 0, 2);
world.setBlock(i+2, j+11, k+11, Block.getBlockById(35), 0, 2);
world.setBlock(i+3, j+11, k+11, Block.getBlockById(35), 0, 2);
world.setBlock(i+4, j+11, k+11, Block.getBlockById(35), 0, 2);
world.setBlock(i+0, j+11, k+12, Block.getBlockById(35), 0, 2);
world.setBlock(i+1, j+11, k+12, Block.getBlockById(35), 0, 2);
world.setBlock(i+2, j+11, k+12, Block.getBlockById(35), 0, 2);
world.setBlock(i+3, j+11, k+12, Block.getBlockById(35), 0, 2);
world.setBlock(i+4, j+11, k+12, Block.getBlockById(35), 0, 2);
world.setBlock(i+1, j+11, k+13, Block.getBlockById(35), 0, 2);
world.setBlock(i+2, j+11, k+13, Block.getBlockById(35), 0, 2);
world.setBlock(i+3, j+11, k+13, Block.getBlockById(35), 0, 2);
world.setBlock(i+1, j+12, k+9, Block.getBlockById(35), 14, 2);
world.setBlock(i+2, j+12, k+9, Block.getBlockById(35), 14, 2);
world.setBlock(i+3, j+12, k+9, Block.getBlockById(35), 14, 2);
world.setBlock(i+0, j+12, k+10, Block.getBlockById(35), 14, 2);
world.setBlock(i+1, j+12, k+10, Block.getBlockById(35), 0, 2);
world.setBlock(i+2, j+12, k+10, Block.getBlockById(35), 0, 2);
world.setBlock(i+3, j+12, k+10, Block.getBlockById(35), 0, 2);
world.setBlock(i+4, j+12, k+10, Block.getBlockById(35), 14, 2);
world.setBlock(i+0, j+12, k+11, Block.getBlockById(35), 14, 2);
world.setBlock(i+1, j+12, k+11, Block.getBlockById(35), 0, 2);
world.setBlock(i+2, j+12, k+11, Block.getBlockById(35), 0, 2);
world.setBlock(i+3, j+12, k+11, Block.getBlockById(35), 0, 2);
world.setBlock(i+4, j+12, k+11, Block.getBlockById(35), 14, 2);
world.setBlock(i+0, j+12, k+12, Block.getBlockById(35), 14, 2);
world.setBlock(i+1, j+12, k+12, Block.getBlockById(35), 0, 2);
world.setBlock(i+2, j+12, k+12, Block.getBlockById(35), 0, 2);
world.setBlock(i+3, j+12, k+12, Block.getBlockById(35), 0, 2);
world.setBlock(i+4, j+12, k+12, Block.getBlockById(35), 14, 2);
world.setBlock(i+1, j+12, k+13, Block.getBlockById(35), 14, 2);
world.setBlock(i+2, j+12, k+13, Block.getBlockById(35), 14, 2);
world.setBlock(i+3, j+12, k+13, Block.getBlockById(35), 14, 2);
world.setBlock(i+1, j+13, k+9, Block.getBlockById(35), 0, 2);
world.setBlock(i+2, j+13, k+9, Block.getBlockById(35), 0, 2);
world.setBlock(i+3, j+13, k+9, Block.getBlockById(35), 0, 2);
world.setBlock(i+0, j+13, k+10, Block.getBlockById(35), 0, 2);
world.setBlock(i+1, j+13, k+10, Block.getBlockById(35), 0, 2);
world.setBlock(i+2, j+13, k+10, Block.getBlockById(35), 0, 2);
world.setBlock(i+3, j+13, k+10, Block.getBlockById(35), 0, 2);
world.setBlock(i+4, j+13, k+10, Block.getBlockById(35), 0, 2);
world.setBlock(i+0, j+13, k+11, Block.getBlockById(35), 0, 2);
world.setBlock(i+1, j+13, k+11, Block.getBlockById(35), 0, 2);
world.setBlock(i+2, j+13, k+11, Block.getBlockById(35), 0, 2);
world.setBlock(i+3, j+13, k+11, Block.getBlockById(35), 0, 2);
world.setBlock(i+4, j+13, k+11, Block.getBlockById(35), 0, 2);
world.setBlock(i+0, j+13, k+12, Block.getBlockById(35), 0, 2);
world.setBlock(i+1, j+13, k+12, Block.getBlockById(35), 0, 2);
world.setBlock(i+2, j+13, k+12, Block.getBlockById(35), 0, 2);
world.setBlock(i+3, j+13, k+12, Block.getBlockById(35), 0, 2);
world.setBlock(i+4, j+13, k+12, Block.getBlockById(35), 0, 2);
world.setBlock(i+1, j+13, k+13, Block.getBlockById(35), 0, 2);
world.setBlock(i+2, j+13, k+13, Block.getBlockById(35), 0, 2);
world.setBlock(i+3, j+13, k+13, Block.getBlockById(35), 0, 2);
world.setBlock(i+1, j+14, k+9, Block.getBlockById(35), 14, 2);
world.setBlock(i+2, j+14, k+9, Block.getBlockById(35), 14, 2);
world.setBlock(i+3, j+14, k+9, Block.getBlockById(35), 14, 2);
world.setBlock(i+0, j+14, k+10, Block.getBlockById(35), 14, 2);
world.setBlock(i+1, j+14, k+10, Block.getBlockById(35), 0, 2);
world.setBlock(i+2, j+14, k+10, Block.getBlockById(35), 0, 2);
world.setBlock(i+3, j+14, k+10, Block.getBlockById(35), 0, 2);
world.setBlock(i+4, j+14, k+10, Block.getBlockById(35), 14, 2);
world.setBlock(i+0, j+14, k+11, Block.getBlockById(35), 14, 2);
world.setBlock(i+1, j+14, k+11, Block.getBlockById(35), 0, 2);
world.setBlock(i+2, j+14, k+11, Block.getBlockById(35), 0, 2);
world.setBlock(i+3, j+14, k+11, Block.getBlockById(35), 0, 2);
world.setBlock(i+4, j+14, k+11, Block.getBlockById(35), 14, 2);
world.setBlock(i+0, j+14, k+12, Block.getBlockById(35), 14, 2);
world.setBlock(i+1, j+14, k+12, Block.getBlockById(35), 0, 2);
world.setBlock(i+2, j+14, k+12, Block.getBlockById(35), 0, 2);
world.setBlock(i+3, j+14, k+12, Block.getBlockById(35), 0, 2);
world.setBlock(i+4, j+14, k+12, Block.getBlockById(35), 14, 2);
world.setBlock(i+1, j+14, k+13, Block.getBlockById(35), 14, 2);
world.setBlock(i+2, j+14, k+13, Block.getBlockById(35), 14, 2);
world.setBlock(i+3, j+14, k+13, Block.getBlockById(35), 14, 2);
world.setBlock(i+2, j+15, k+2, Block.getBlockById(35), 14, 2);
world.setBlock(i+1, j+15, k+9, Block.getBlockById(35), 0, 2);
world.setBlock(i+2, j+15, k+9, Block.getBlockById(35), 0, 2);
world.setBlock(i+3, j+15, k+9, Block.getBlockById(35), 0, 2);
world.setBlock(i+0, j+15, k+10, Block.getBlockById(35), 0, 2);
world.setBlock(i+1, j+15, k+10, Block.getBlockById(35), 0, 2);
world.setBlock(i+2, j+15, k+10, Block.getBlockById(35), 0, 2);
world.setBlock(i+3, j+15, k+10, Block.getBlockById(35), 0, 2);
world.setBlock(i+4, j+15, k+10, Block.getBlockById(35), 0, 2);
world.setBlock(i+0, j+15, k+11, Block.getBlockById(35), 0, 2);
world.setBlock(i+1, j+15, k+11, Block.getBlockById(35), 0, 2);
world.setBlock(i+2, j+15, k+11, Block.getBlockById(35), 0, 2);
world.setBlock(i+3, j+15, k+11, Block.getBlockById(35), 0, 2);
world.setBlock(i+4, j+15, k+11, Block.getBlockById(35), 0, 2);
world.setBlock(i+0, j+15, k+12, Block.getBlockById(35), 0, 2);
world.setBlock(i+1, j+15, k+12, Block.getBlockById(35), 0, 2);
world.setBlock(i+2, j+15, k+12, Block.getBlockById(35), 0, 2);
world.setBlock(i+3, j+15, k+12, Block.getBlockById(35), 0, 2);
world.setBlock(i+4, j+15, k+12, Block.getBlockById(35), 0, 2);
world.setBlock(i+1, j+15, k+13, Block.getBlockById(35), 0, 2);
world.setBlock(i+2, j+15, k+13, Block.getBlockById(35), 0, 2);
world.setBlock(i+3, j+15, k+13, Block.getBlockById(35), 0, 2);
world.setBlock(i+2, j+16, k+1, Block.getBlockById(35), 0, 2);
world.setBlock(i+1, j+16, k+2, Block.getBlockById(35), 0, 2);
world.setBlock(i+2, j+16, k+2, Block.getBlockById(35), 0, 2);
world.setBlock(i+3, j+16, k+2, Block.getBlockById(35), 0, 2);
world.setBlock(i+2, j+16, k+3, Block.getBlockById(35), 0, 2);
world.setBlock(i+1, j+16, k+9, Block.getBlockById(35), 14, 2);
world.setBlock(i+2, j+16, k+9, Block.getBlockById(35), 14, 2);
world.setBlock(i+3, j+16, k+9, Block.getBlockById(35), 14, 2);
world.setBlock(i+0, j+16, k+10, Block.getBlockById(35), 14, 2);
world.setBlock(i+1, j+16, k+10, Block.getBlockById(35), 0, 2);
world.setBlock(i+2, j+16, k+10, Block.getBlockById(35), 0, 2);
world.setBlock(i+3, j+16, k+10, Block.getBlockById(35), 0, 2);
world.setBlock(i+4, j+16, k+10, Block.getBlockById(35), 14, 2);
world.setBlock(i+0, j+16, k+11, Block.getBlockById(35), 14, 2);
world.setBlock(i+1, j+16, k+11, Block.getBlockById(35), 0, 2);
world.setBlock(i+2, j+16, k+11, Block.getBlockById(35), 0, 2);
world.setBlock(i+3, j+16, k+11, Block.getBlockById(35), 0, 2);
world.setBlock(i+4, j+16, k+11, Block.getBlockById(35), 14, 2);
world.setBlock(i+0, j+16, k+12, Block.getBlockById(35), 14, 2);
world.setBlock(i+1, j+16, k+12, Block.getBlockById(35), 0, 2);
world.setBlock(i+2, j+16, k+12, Block.getBlockById(35), 0, 2);
world.setBlock(i+3, j+16, k+12, Block.getBlockById(35), 0, 2);
world.setBlock(i+4, j+16, k+12, Block.getBlockById(35), 14, 2);
world.setBlock(i+1, j+16, k+13, Block.getBlockById(35), 14, 2);
world.setBlock(i+2, j+16, k+13, Block.getBlockById(35), 14, 2);
world.setBlock(i+3, j+16, k+13, Block.getBlockById(35), 14, 2);
world.setBlock(i+2, j+17, k+0, Block.getBlockById(35), 0, 2);
world.setBlock(i+1, j+17, k+1, Block.getBlockById(35), 0, 2);
world.setBlock(i+2, j+17, k+1, Block.getBlockById(35), 0, 2);
world.setBlock(i+3, j+17, k+1, Block.getBlockById(35), 0, 2);
world.setBlock(i+1, j+17, k+2, Block.getBlockById(35), 0, 2);
world.setBlock(i+2, j+17, k+2, Block.getBlockById(35), 0, 2);
world.setBlock(i+3, j+17, k+2, Block.getBlockById(35), 0, 2);
world.setBlock(i+1, j+17, k+3, Block.getBlockById(35), 0, 2);
world.setBlock(i+2, j+17, k+3, Block.getBlockById(35), 0, 2);
world.setBlock(i+3, j+17, k+3, Block.getBlockById(35), 0, 2);
world.setBlock(i+2, j+17, k+4, Block.getBlockById(35), 0, 2);
world.setBlock(i+1, j+17, k+9, Block.getBlockById(35), 0, 2);
world.setBlock(i+2, j+17, k+9, Block.getBlockById(35), 0, 2);
world.setBlock(i+3, j+17, k+9, Block.getBlockById(35), 0, 2);
world.setBlock(i+0, j+17, k+10, Block.getBlockById(35), 0, 2);
world.setBlock(i+1, j+17, k+10, Block.getBlockById(35), 0, 2);
world.setBlock(i+2, j+17, k+10, Block.getBlockById(35), 0, 2);
world.setBlock(i+3, j+17, k+10, Block.getBlockById(35), 0, 2);
world.setBlock(i+4, j+17, k+10, Block.getBlockById(35), 0, 2);
world.setBlock(i+0, j+17, k+11, Block.getBlockById(35), 0, 2);
world.setBlock(i+1, j+17, k+11, Block.getBlockById(35), 0, 2);
world.setBlock(i+2, j+17, k+11, Block.getBlockById(35), 0, 2);
world.setBlock(i+3, j+17, k+11, Block.getBlockById(35), 0, 2);
world.setBlock(i+4, j+17, k+11, Block.getBlockById(35), 0, 2);
world.setBlock(i+0, j+17, k+12, Block.getBlockById(35), 0, 2);
world.setBlock(i+1, j+17, k+12, Block.getBlockById(35), 0, 2);
world.setBlock(i+2, j+17, k+12, Block.getBlockById(35), 0, 2);
world.setBlock(i+3, j+17, k+12, Block.getBlockById(35), 0, 2);
world.setBlock(i+4, j+17, k+12, Block.getBlockById(35), 0, 2);
world.setBlock(i+1, j+17, k+13, Block.getBlockById(35), 0, 2);
world.setBlock(i+2, j+17, k+13, Block.getBlockById(35), 0, 2);
world.setBlock(i+3, j+17, k+13, Block.getBlockById(35), 0, 2);
world.setBlock(i+2, j+18, k+0, Block.getBlockById(35), 0, 2);
world.setBlock(i+1, j+18, k+1, Block.getBlockById(35), 14, 2);
world.setBlock(i+2, j+18, k+1, Block.getBlockById(35), 0, 2);
world.setBlock(i+3, j+18, k+1, Block.getBlockById(35), 14, 2);
world.setBlock(i+0, j+18, k+2, Block.getBlockById(35), 14, 2);
world.setBlock(i+1, j+18, k+2, Block.getBlockById(35), 0, 2);
world.setBlock(i+2, j+18, k+2, Block.getBlockById(35), 0, 2);
world.setBlock(i+3, j+18, k+2, Block.getBlockById(35), 0, 2);
world.setBlock(i+4, j+18, k+2, Block.getBlockById(35), 14, 2);
world.setBlock(i+0, j+18, k+3, Block.getBlockById(35), 0, 2);
world.setBlock(i+1, j+18, k+3, Block.getBlockById(35), 0, 2);
world.setBlock(i+2, j+18, k+3, Block.getBlockById(35), 0, 2);
world.setBlock(i+3, j+18, k+3, Block.getBlockById(35), 0, 2);
world.setBlock(i+4, j+18, k+3, Block.getBlockById(35), 0, 2);
world.setBlock(i+1, j+18, k+4, Block.getBlockById(35), 0, 2);
world.setBlock(i+2, j+18, k+4, Block.getBlockById(35), 0, 2);
world.setBlock(i+3, j+18, k+4, Block.getBlockById(35), 0, 2);
world.setBlock(i+2, j+18, k+5, Block.getBlockById(35), 0, 2);
world.setBlock(i+1, j+18, k+9, Block.getBlockById(35), 14, 2);
world.setBlock(i+2, j+18, k+9, Block.getBlockById(35), 14, 2);
world.setBlock(i+3, j+18, k+9, Block.getBlockById(35), 14, 2);
world.setBlock(i+0, j+18, k+10, Block.getBlockById(35), 14, 2);
world.setBlock(i+1, j+18, k+10, Block.getBlockById(35), 0, 2);
world.setBlock(i+2, j+18, k+10, Block.getBlockById(35), 0, 2);
world.setBlock(i+3, j+18, k+10, Block.getBlockById(35), 0, 2);
world.setBlock(i+4, j+18, k+10, Block.getBlockById(35), 14, 2);
world.setBlock(i+0, j+18, k+11, Block.getBlockById(35), 14, 2);
world.setBlock(i+1, j+18, k+11, Block.getBlockById(35), 0, 2);
world.setBlock(i+2, j+18, k+11, Block.getBlockById(35), 0, 2);
world.setBlock(i+3, j+18, k+11, Block.getBlockById(35), 0, 2);
world.setBlock(i+4, j+18, k+11, Block.getBlockById(35), 14, 2);
world.setBlock(i+0, j+18, k+12, Block.getBlockById(35), 14, 2);
world.setBlock(i+1, j+18, k+12, Block.getBlockById(35), 0, 2);
world.setBlock(i+2, j+18, k+12, Block.getBlockById(35), 0, 2);
world.setBlock(i+3, j+18, k+12, Block.getBlockById(35), 0, 2);
world.setBlock(i+4, j+18, k+12, Block.getBlockById(35), 14, 2);
world.setBlock(i+1, j+18, k+13, Block.getBlockById(35), 14, 2);
world.setBlock(i+2, j+18, k+13, Block.getBlockById(35), 14, 2);
world.setBlock(i+3, j+18, k+13, Block.getBlockById(35), 14, 2);
world.setBlock(i+1, j+19, k+1, Block.getBlockById(35), 14, 2);
world.setBlock(i+2, j+19, k+1, Block.getBlockById(35), 0, 2);
world.setBlock(i+3, j+19, k+1, Block.getBlockById(35), 14, 2);
world.setBlock(i+0, j+19, k+2, Block.getBlockById(35), 0, 2);
world.setBlock(i+1, j+19, k+2, Block.getBlockById(35), 0, 2);
world.setBlock(i+2, j+19, k+2, Block.getBlockById(35), 0, 2);
world.setBlock(i+3, j+19, k+2, Block.getBlockById(35), 0, 2);
world.setBlock(i+4, j+19, k+2, Block.getBlockById(35), 0, 2);
world.setBlock(i+0, j+19, k+3, Block.getBlockById(35), 0, 2);
world.setBlock(i+1, j+19, k+3, Block.getBlockById(35), 0, 2);
world.setBlock(i+2, j+19, k+3, Block.getBlockById(35), 0, 2);
world.setBlock(i+3, j+19, k+3, Block.getBlockById(35), 0, 2);
world.setBlock(i+4, j+19, k+3, Block.getBlockById(35), 0, 2);
world.setBlock(i+0, j+19, k+4, Block.getBlockById(35), 14, 2);
world.setBlock(i+1, j+19, k+4, Block.getBlockById(35), 0, 2);
world.setBlock(i+2, j+19, k+4, Block.getBlockById(35), 0, 2);
world.setBlock(i+3, j+19, k+4, Block.getBlockById(35), 0, 2);
world.setBlock(i+4, j+19, k+4, Block.getBlockById(35), 14, 2);
world.setBlock(i+1, j+19, k+5, Block.getBlockById(35), 0, 2);
world.setBlock(i+2, j+19, k+5, Block.getBlockById(35), 0, 2);
world.setBlock(i+3, j+19, k+5, Block.getBlockById(35), 0, 2);
world.setBlock(i+1, j+19, k+6, Block.getBlockById(35), 14, 2);
world.setBlock(i+2, j+19, k+6, Block.getBlockById(35), 0, 2);
world.setBlock(i+3, j+19, k+6, Block.getBlockById(35), 14, 2);
world.setBlock(i+1, j+19, k+7, Block.getBlockById(35), 0, 2);
world.setBlock(i+2, j+19, k+7, Block.getBlockById(35), 0, 2);
world.setBlock(i+3, j+19, k+7, Block.getBlockById(35), 0, 2);
world.setBlock(i+1, j+19, k+8, Block.getBlockById(35), 0, 2);
world.setBlock(i+2, j+19, k+8, Block.getBlockById(35), 0, 2);
world.setBlock(i+3, j+19, k+8, Block.getBlockById(35), 0, 2);
world.setBlock(i+0, j+19, k+9, Block.getBlockById(35), 0, 2);
world.setBlock(i+1, j+19, k+9, Block.getBlockById(35), 0, 2);
world.setBlock(i+2, j+19, k+9, Block.getBlockById(35), 0, 2);
world.setBlock(i+3, j+19, k+9, Block.getBlockById(35), 0, 2);
world.setBlock(i+4, j+19, k+9, Block.getBlockById(35), 0, 2);
world.setBlock(i+0, j+19, k+10, Block.getBlockById(35), 0, 2);
world.setBlock(i+1, j+19, k+10, Block.getBlockById(35), 0, 2);
world.setBlock(i+2, j+19, k+10, Block.getBlockById(35), 0, 2);
world.setBlock(i+3, j+19, k+10, Block.getBlockById(35), 0, 2);
world.setBlock(i+4, j+19, k+10, Block.getBlockById(35), 0, 2);
world.setBlock(i+0, j+19, k+11, Block.getBlockById(35), 0, 2);
world.setBlock(i+1, j+19, k+11, Block.getBlockById(35), 0, 2);
world.setBlock(i+2, j+19, k+11, Block.getBlockById(35), 0, 2);
world.setBlock(i+3, j+19, k+11, Block.getBlockById(35), 0, 2);
world.setBlock(i+4, j+19, k+11, Block.getBlockById(35), 0, 2);
world.setBlock(i+0, j+19, k+12, Block.getBlockById(35), 0, 2);
world.setBlock(i+1, j+19, k+12, Block.getBlockById(35), 0, 2);
world.setBlock(i+2, j+19, k+12, Block.getBlockById(35), 0, 2);
world.setBlock(i+3, j+19, k+12, Block.getBlockById(35), 0, 2);
world.setBlock(i+4, j+19, k+12, Block.getBlockById(35), 0, 2);
world.setBlock(i+2, j+19, k+13, Block.getBlockById(35), 0, 2);
world.setBlock(i+2, j+20, k+1, Block.getBlockById(35), 14, 2);
world.setBlock(i+1, j+20, k+2, Block.getBlockById(35), 0, 2);
world.setBlock(i+2, j+20, k+2, Block.getBlockById(35), 0, 2);
world.setBlock(i+3, j+20, k+2, Block.getBlockById(35), 0, 2);
world.setBlock(i+0, j+20, k+3, Block.getBlockById(35), 0, 2);
world.setBlock(i+1, j+20, k+3, Block.getBlockById(35), 0, 2);
world.setBlock(i+2, j+20, k+3, Block.getBlockById(35), 0, 2);
world.setBlock(i+3, j+20, k+3, Block.getBlockById(35), 0, 2);
world.setBlock(i+4, j+20, k+3, Block.getBlockById(35), 0, 2);
world.setBlock(i+0, j+20, k+4, Block.getBlockById(35), 14, 2);
world.setBlock(i+1, j+20, k+4, Block.getBlockById(35), 0, 2);
world.setBlock(i+2, j+20, k+4, Block.getBlockById(35), 0, 2);
world.setBlock(i+3, j+20, k+4, Block.getBlockById(35), 0, 2);
world.setBlock(i+4, j+20, k+4, Block.getBlockById(35), 14, 2);
world.setBlock(i+0, j+20, k+5, Block.getBlockById(35), 0, 2);
world.setBlock(i+1, j+20, k+5, Block.getBlockById(35), 0, 2);
world.setBlock(i+2, j+20, k+5, Block.getBlockById(35), 0, 2);
world.setBlock(i+3, j+20, k+5, Block.getBlockById(35), 0, 2);
world.setBlock(i+4, j+20, k+5, Block.getBlockById(35), 0, 2);
world.setBlock(i+0, j+20, k+6, Block.getBlockById(35), 14, 2);
world.setBlock(i+1, j+20, k+6, Block.getBlockById(35), 0, 2);
world.setBlock(i+2, j+20, k+6, Block.getBlockById(35), 0, 2);
world.setBlock(i+3, j+20, k+6, Block.getBlockById(35), 0, 2);
world.setBlock(i+4, j+20, k+6, Block.getBlockById(35), 14, 2);
world.setBlock(i+0, j+20, k+7, Block.getBlockById(35), 0, 2);
world.setBlock(i+1, j+20, k+7, Block.getBlockById(35), 0, 2);
world.setBlock(i+2, j+20, k+7, Block.getBlockById(35), 0, 2);
world.setBlock(i+3, j+20, k+7, Block.getBlockById(35), 0, 2);
world.setBlock(i+4, j+20, k+7, Block.getBlockById(35), 0, 2);
world.setBlock(i+0, j+20, k+8, Block.getBlockById(35), 0, 2);
world.setBlock(i+1, j+20, k+8, Block.getBlockById(35), 0, 2);
world.setBlock(i+2, j+20, k+8, Block.getBlockById(35), 0, 2);
world.setBlock(i+3, j+20, k+8, Block.getBlockById(35), 0, 2);
world.setBlock(i+4, j+20, k+8, Block.getBlockById(35), 0, 2);
world.setBlock(i+0, j+20, k+9, Block.getBlockById(35), 14, 2);
world.setBlock(i+1, j+20, k+9, Block.getBlockById(35), 0, 2);
world.setBlock(i+2, j+20, k+9, Block.getBlockById(35), 0, 2);
world.setBlock(i+3, j+20, k+9, Block.getBlockById(35), 0, 2);
world.setBlock(i+4, j+20, k+9, Block.getBlockById(35), 14, 2);
world.setBlock(i+0, j+20, k+10, Block.getBlockById(35), 14, 2);
world.setBlock(i+1, j+20, k+10, Block.getBlockById(35), 0, 2);
world.setBlock(i+2, j+20, k+10, Block.getBlockById(35), 0, 2);
world.setBlock(i+3, j+20, k+10, Block.getBlockById(35), 0, 2);
world.setBlock(i+4, j+20, k+10, Block.getBlockById(35), 14, 2);
world.setBlock(i+0, j+20, k+11, Block.getBlockById(35), 0, 2);
world.setBlock(i+1, j+20, k+11, Block.getBlockById(35), 0, 2);
world.setBlock(i+2, j+20, k+11, Block.getBlockById(35), 0, 2);
world.setBlock(i+3, j+20, k+11, Block.getBlockById(35), 0, 2);
world.setBlock(i+4, j+20, k+11, Block.getBlockById(35), 0, 2);
world.setBlock(i+1, j+20, k+12, Block.getBlockById(35), 0, 2);
world.setBlock(i+2, j+20, k+12, Block.getBlockById(35), 14, 2);
world.setBlock(i+3, j+20, k+12, Block.getBlockById(35), 0, 2);
world.setBlock(i+2, j+21, k+1, Block.getBlockById(35), 0, 2);
world.setBlock(i+1, j+21, k+2, Block.getBlockById(35), 0, 2);
world.setBlock(i+2, j+21, k+2, Block.getBlockById(35), 0, 2);
world.setBlock(i+3, j+21, k+2, Block.getBlockById(35), 0, 2);
world.setBlock(i+0, j+21, k+3, Block.getBlockById(35), 0, 2);
world.setBlock(i+1, j+21, k+3, Block.getBlockById(35), 0, 2);
world.setBlock(i+2, j+21, k+3, Block.getBlockById(35), 0, 2);
world.setBlock(i+3, j+21, k+3, Block.getBlockById(35), 0, 2);
world.setBlock(i+4, j+21, k+3, Block.getBlockById(35), 0, 2);
world.setBlock(i+0, j+21, k+4, Block.getBlockById(35), 14, 2);
world.setBlock(i+1, j+21, k+4, Block.getBlockById(35), 0, 2);
world.setBlock(i+2, j+21, k+4, Block.getBlockById(35), 0, 2);
world.setBlock(i+3, j+21, k+4, Block.getBlockById(35), 0, 2);
world.setBlock(i+4, j+21, k+4, Block.getBlockById(35), 14, 2);
world.setBlock(i+0, j+21, k+5, Block.getBlockById(35), 0, 2);
world.setBlock(i+1, j+21, k+5, Block.getBlockById(35), 0, 2);
world.setBlock(i+2, j+21, k+5, Block.getBlockById(35), 0, 2);
world.setBlock(i+3, j+21, k+5, Block.getBlockById(35), 0, 2);
world.setBlock(i+4, j+21, k+5, Block.getBlockById(35), 0, 2);
world.setBlock(i+0, j+21, k+6, Block.getBlockById(35), 0, 2);
world.setBlock(i+1, j+21, k+6, Block.getBlockById(35), 0, 2);
world.setBlock(i+2, j+21, k+6, Block.getBlockById(35), 0, 2);
world.setBlock(i+3, j+21, k+6, Block.getBlockById(35), 0, 2);
world.setBlock(i+4, j+21, k+6, Block.getBlockById(35), 0, 2);
world.setBlock(i+0, j+21, k+7, Block.getBlockById(35), 14, 2);
world.setBlock(i+1, j+21, k+7, Block.getBlockById(35), 0, 2);
world.setBlock(i+2, j+21, k+7, Block.getBlockById(35), 0, 2);
world.setBlock(i+3, j+21, k+7, Block.getBlockById(35), 0, 2);
world.setBlock(i+4, j+21, k+7, Block.getBlockById(35), 14, 2);
world.setBlock(i+0, j+21, k+8, Block.getBlockById(35), 0, 2);
world.setBlock(i+1, j+21, k+8, Block.getBlockById(35), 0, 2);
world.setBlock(i+2, j+21, k+8, Block.getBlockById(35), 0, 2);
world.setBlock(i+3, j+21, k+8, Block.getBlockById(35), 0, 2);
world.setBlock(i+4, j+21, k+8, Block.getBlockById(35), 0, 2);
world.setBlock(i+0, j+21, k+9, Block.getBlockById(35), 0, 2);
world.setBlock(i+1, j+21, k+9, Block.getBlockById(35), 0, 2);
world.setBlock(i+2, j+21, k+9, Block.getBlockById(35), 0, 2);
world.setBlock(i+3, j+21, k+9, Block.getBlockById(35), 0, 2);
world.setBlock(i+4, j+21, k+9, Block.getBlockById(35), 0, 2);
world.setBlock(i+0, j+21, k+10, Block.getBlockById(78), 0, 2);
world.setBlock(i+1, j+21, k+10, Block.getBlockById(35), 14, 2);
world.setBlock(i+2, j+21, k+10, Block.getBlockById(35), 0, 2);
world.setBlock(i+3, j+21, k+10, Block.getBlockById(35), 14, 2);
world.setBlock(i+4, j+21, k+10, Block.getBlockById(78), 0, 2);
world.setBlock(i+1, j+21, k+11, Block.getBlockById(35), 14, 2);
world.setBlock(i+2, j+21, k+11, Block.getBlockById(35), 0, 2);
world.setBlock(i+3, j+21, k+11, Block.getBlockById(35), 14, 2);
world.setBlock(i+2, j+21, k+12, Block.getBlockById(35), 14, 2);
world.setBlock(i+2, j+22, k+2, Block.getBlockById(78), 0, 2);
world.setBlock(i+1, j+22, k+3, Block.getBlockById(78), 0, 2);
world.setBlock(i+2, j+22, k+3, Block.getBlockById(35), 0, 2);
world.setBlock(i+3, j+22, k+3, Block.getBlockById(78), 0, 2);
world.setBlock(i+1, j+22, k+4, Block.getBlockById(35), 14, 2);
world.setBlock(i+2, j+22, k+4, Block.getBlockById(35), 0, 2);
world.setBlock(i+3, j+22, k+4, Block.getBlockById(35), 14, 2);
world.setBlock(i+1, j+22, k+5, Block.getBlockById(35), 14, 2);
world.setBlock(i+2, j+22, k+5, Block.getBlockById(35), 0, 2);
world.setBlock(i+3, j+22, k+5, Block.getBlockById(35), 14, 2);
world.setBlock(i+1, j+22, k+6, Block.getBlockById(35), 0, 2);
world.setBlock(i+2, j+22, k+6, Block.getBlockById(35), 0, 2);
world.setBlock(i+3, j+22, k+6, Block.getBlockById(35), 0, 2);
world.setBlock(i+1, j+22, k+7, Block.getBlockById(35), 14, 2);
world.setBlock(i+2, j+22, k+7, Block.getBlockById(35), 0, 2);
world.setBlock(i+3, j+22, k+7, Block.getBlockById(35), 14, 2);
world.setBlock(i+1, j+22, k+8, Block.getBlockById(35), 14, 2);
world.setBlock(i+2, j+22, k+8, Block.getBlockById(35), 0, 2);
world.setBlock(i+3, j+22, k+8, Block.getBlockById(35), 14, 2);
world.setBlock(i+1, j+22, k+9, Block.getBlockById(35), 0, 2);
world.setBlock(i+2, j+22, k+9, Block.getBlockById(35), 0, 2);
world.setBlock(i+3, j+22, k+9, Block.getBlockById(35), 0, 2);
world.setBlock(i+4, j+22, k+9, Block.getBlockById(78), 0, 2);
world.setBlock(i+1, j+22, k+10, Block.getBlockById(78), 0, 2);
world.setBlock(i+2, j+22, k+10, Block.getBlockById(35), 0, 2);
world.setBlock(i+3, j+22, k+10, Block.getBlockById(78), 0, 2);
world.setBlock(i+2, j+22, k+11, Block.getBlockById(35), 0, 2);
world.setBlock(i+2, j+23, k+4, Block.getBlockById(35), 0, 2);
world.setBlock(i+1, j+23, k+5, Block.getBlockById(35), 14, 2);
world.setBlock(i+2, j+23, k+5, Block.getBlockById(35), 14, 2);
world.setBlock(i+3, j+23, k+5, Block.getBlockById(35), 14, 2);
world.setBlock(i+1, j+23, k+6, Block.getBlockById(35), 0, 2);
world.setBlock(i+2, j+23, k+6, Block.getBlockById(35), 0, 2);
world.setBlock(i+3, j+23, k+6, Block.getBlockById(35), 0, 2);
world.setBlock(i+1, j+23, k+7, Block.getBlockById(35), 0, 2);
world.setBlock(i+2, j+23, k+7, Block.getBlockById(35), 0, 2);
world.setBlock(i+3, j+23, k+7, Block.getBlockById(35), 0, 2);
world.setBlock(i+1, j+23, k+8, Block.getBlockById(35), 14, 2);
world.setBlock(i+2, j+23, k+8, Block.getBlockById(35), 0, 2);
world.setBlock(i+3, j+23, k+8, Block.getBlockById(35), 14, 2);
world.setBlock(i+1, j+23, k+9, Block.getBlockById(78), 0, 2);
world.setBlock(i+2, j+23, k+9, Block.getBlockById(35), 14, 2);
world.setBlock(i+3, j+23, k+9, Block.getBlockById(78), 0, 2);
world.setBlock(i+2, j+23, k+10, Block.getBlockById(78), 0, 2);
world.setBlock(i+2, j+23, k+11, Block.getBlockById(78), 0, 2);
world.setBlock(i+2, j+24, k+5, Block.getBlockById(78), 0, 2);
world.setBlock(i+2, j+24, k+6, Block.getBlockById(78), 0, 2);
world.setBlock(i+2, j+24, k+7, Block.getBlockById(78), 0, 2);
world.setBlock(i+1, j+24, k+8, Block.getBlockById(78), 0, 2);
world.setBlock(i+2, j+24, k+8, Block.getBlockById(78), 0, 2);
world.setBlock(i+3, j+24, k+8, Block.getBlockById(78), 0, 2);
world.setBlock(i+2, j+24, k+9, Block.getBlockById(78), 0, 2);
}
}

return true;
}




}


}
